Workbook

Sheet Start Here
B2: Tigrinya Top 1,000 Words — Learning Edition
B3: ትግርኛ ንቈልዑ — Tigrinya for kids of the Eritrean diaspora
B5: What this is | C5: The 1,000 most frequent Tigrinya words found across newspapers, websites, blogs, books and magazines (word list and frequency counts compiled by Fitsum Gaim, MIT). For each word, this edition adds a romanized pronunciation, an English meaning, the kind of word it is, a topic, a learning level, a short example sentence (Tigrinya, romanized, and English), and a learning note written for English-speaking kids and the parents teaching them.
B6: Where to begin | C6: Open the 'Starter Words' tab. It lists the Level 1 words grouped by topic — greetings, family, numbers, question words, and the small grammar words every sentence needs. When those feel easy, use the filter on the 'Word List' tab to show Level 2 (Core) words, and so on.
B7: Reading the sounds | C7: See the 'Pronunciation Guide' tab. Quick version: syllables are split with hyphens (tim-hir-ti); an apostrophe right after t, ts, ch or p means a popped sound (t'i-ray); q is a deep 'k' from the back of the throat; kh is a soft throaty sound like the end of 'Bach'.
B8: Boys, girls, groups | C8: Tigrinya changes many words depending on who you're talking to. Example sentences are marked '(to a boy)', '(to a girl)' or '(to a group)', and the learning notes give the other forms (e.g., ከመይ ኣለኻ? to a boy, ከመይ ኣለኺ? to a girl).
B10: Learning levels
B11: 1 Starter | C11: First words to learn: greetings, family, numbers, question words, everyday nouns, and core grammar words.
B12: 2 Core | C12: Common words for building real sentences and following everyday conversation.
B13: 3 Advanced | C13: Words common in reading — news, stories, school — useful for older kids and teens.
B14: 4 Specialized | C14: Mostly from newspapers (court and legal notices), sports clubs, personal names, religious texts, or split word pieces. Good to recognize; not a priority.
B16: Columns in the Word List
B17: Rank / Tigrinya Word / Frequency | C17: Unchanged from the original list, in the original order. Frequency = number of times the word appeared in the source texts.
B18: Pronunciation | C18: Romanized, kid-friendly spelling split into syllables. See the Pronunciation Guide.
B19: English Meaning | C19: The main meaning(s). Many Tigrinya words cover several English words.
B20: Word Type | C20: Noun, verb form, pointing word (the/this/that), linking word (is/are), and so on.
B21: Topic | C21: One of 21 themes, so you can study related words together (e.g., Time & Calendar, Food & Drink).
B22: Level | C22: 1 Starter → 4 Specialized (see above).
B23: Example (3 columns) | C23: A short sentence or phrase using the word, shown in Tigrinya, in romanized form, and in English.
B24: Learning Note | C24: Grammar tips, related words, male/female/plural forms, and cultural background.
B25: Needs Review | C25: Marked 'Check' where the meaning or usage is uncertain. Please confirm these with a fluent speaker before teaching them.
B27: About the source data
B28: Newspaper legal notices | C28: A large share of the source text comes from court notices in Eritrean newspapers (ሓዳስ ኤርትራ). That is why words like ዝቃወም ('anyone who objects'), ይቕረብ ('let him appear'), ወረስቲ ('heirs') and ይረጋገጸልና ('let it be confirmed for us') rank so high. They are tagged 'Law & Courts' and Level 4.
B29: Religion and sports | C29: Religious publications and European soccer coverage are also well represented — hence የሆዋ (Jehovah), ቸልሲ (Chelsea), ኣርሰናል (Arsenal), and ማን / ሲቲ (pieces of "Man City").
B30: Split forms | C30: About 15 entries aren't full words but pieces split off at apostrophes (ዩ from እዩ, ውን from እውን, ዚ, ቲ, የ, ያ) or softened spellings (ኸም for ከም, ኻብ for ካብ). Each is labeled 'Short / split form' and points to the full word.
B31: Spelling variants | C31: Some words appear more than once with different spellings (ኮይኑ / ኰይኑ / ዀይኑ, ኩሉ / ኵሉ / ዅሉ, ተመሃሮ / ተማሃሮ). The learning notes cross-reference them.
B32: Order | C32: The original order was kept. In a few places neighboring rows are slightly out of frequency order in the source (e.g., ranks 110 and 111).
B34: Please note | C34: The pronunciations, translations, and example sentences were written for learners and checked for consistency with the Ge'ez spelling, but they have not been reviewed by a native speaker. Before using this with children, have a fluent Tigrinya speaker look over the examples (especially rows marked 'Check'), since phrasing and word choice can vary by region and family.
B36: Credit | C36: Original word list and frequencies: Fitsum Gaim (MIT). Learning data added in this edition.

Sheet Starter Words
A1: Starter Words — the first words to learn, grouped by topic
A2: Every cell links back to the Word List, so edits there show up here. Words are in frequency order within each topic.
A4: Topic | B4: Rank | C4: Tigrinya | D4: Pronunciation | E4: English Meaning | F4: Example (Tigrinya) | G4: Example (Romanized) | H4: Example (English)
A5: ='Word List'!G2 -> Grammar Essentials | B5: ='Word List'!A2 -> 1 | C5: ='Word List'!B2 -> ኣብ | D5: ='Word List'!D2 -> ab | E5: ='Word List'!E2 -> at, in, on | F5: ='Word List'!I2 -> ኣብ ገዛ ኣለኹ። | G5: ='Word List'!J2 -> ab geza allekhu. | H5: ='Word List'!K2 -> I am at home.
A6: ='Word List'!G3 -> Grammar Essentials | B6: ='Word List'!A3 -> 2 | C6: ='Word List'!B3 -> ናይ | D6: ='Word List'!D3 -> nay | E6: ='Word List'!E3 -> of; belonging to ('s) | F6: ='Word List'!I3 -> ናይ ኣደይ መኪና | G6: ='Word List'!J3 -> nay adey mekina | H6: ='Word List'!K3 -> my mother's car
A7: ='Word List'!G4 -> Grammar Essentials | B7: ='Word List'!A4 -> 3 | C7: ='Word List'!B4 -> እዩ | D7: ='Word List'!D4 -> i-yu | E7: ='Word List'!E4 -> is (he/it is) | F7: ='Word List'!I4 -> እዚ ማይ እዩ። | G7: ='Word List'!J4 -> izi may iyu. | H7: ='Word List'!K4 -> This is water.
A8: ='Word List'!G5 -> Grammar Essentials | B8: ='Word List'!A5 -> 4 | C8: ='Word List'!B5 -> ካብ | D8: ='Word List'!D5 -> kab | E8: ='Word List'!E5 -> from | F8: ='Word List'!I5 -> ካብ ኣስመራ እየ። | G8: ='Word List'!J5 -> kab asmera iye. | H8: ='Word List'!K5 -> I am from Asmara.
A9: ='Word List'!G6 -> Grammar Essentials | B9: ='Word List'!A6 -> 5 | C9: ='Word List'!B6 -> ከም | D9: ='Word List'!D6 -> kem | E9: ='Word List'!E6 -> like, as | F9: ='Word List'!I6 -> ከም ኣቦኻ ኢኻ። | G9: ='Word List'!J6 -> kem abokha ikha. | H9: ='Word List'!K6 -> You are like your father.
A10: ='Word List'!G7 -> Grammar Essentials | B10: ='Word List'!A7 -> 6 | C10: ='Word List'!B7 -> እቲ | D10: ='Word List'!D7 -> i-ti | E10: ='Word List'!E7 -> the; that (masculine) | F10: ='Word List'!I7 -> እቲ ቈልዓ ይጻወት ኣሎ። | G10: ='Word List'!J7 -> iti qol'a yits'awet allo. | H10: ='Word List'!K7 -> The child is playing.
A11: ='Word List'!G8 -> Grammar Essentials | B11: ='Word List'!A8 -> 7 | C11: ='Word List'!B8 -> ድማ | D11: ='Word List'!D8 -> dim-ma | E11: ='Word List'!E8 -> and; also | F11: ='Word List'!I8 -> ኣነ ድማ ክመጽእ እየ። | G11: ='Word List'!J8 -> ane dimma kimets'i iye. | H11: ='Word List'!K8 -> And I will come too.
A12: ='Word List'!G9 -> Grammar Essentials | B12: ='Word List'!A9 -> 8 | C12: ='Word List'!B9 -> ምስ | D12: ='Word List'!D9 -> mis | E12: ='Word List'!E9 -> with | F12: ='Word List'!I9 -> ምስ ኣደይ ከይደ። | G12: ='Word List'!J9 -> mis adey keyde. | H12: ='Word List'!K9 -> I went with my mother.
A13: ='Word List'!G10 -> Grammar Essentials | B13: ='Word List'!A10 -> 9 | C13: ='Word List'!B10 -> ናብ | D13: ='Word List'!D10 -> nab | E13: ='Word List'!E10 -> to, toward | F13: ='Word List'!I10 -> ናብ ቤት ትምህርቲ ንኸይድ ኣለና። | G13: ='Word List'!J10 -> nab bet timhirti nikheyd allena. | H13: ='Word List'!K10 -> We are going to school.
A14: ='Word List'!G11 -> Grammar Essentials | B14: ='Word List'!A11 -> 10 | C14: ='Word List'!B11 -> እዚ | D14: ='Word List'!D11 -> i-zi | E14: ='Word List'!E11 -> this (masculine) | F14: ='Word List'!I11 -> እዚ እንታይ እዩ? | G14: ='Word List'!J11 -> izi intay iyu? | H14: ='Word List'!K11 -> What is this?
A15: ='Word List'!G15 -> Grammar Essentials | B15: ='Word List'!A15 -> 14 | C15: ='Word List'!B15 -> ከኣ | D15: ='Word List'!D15 -> ke-a | E15: ='Word List'!E15 -> and; also | F15: ='Word List'!I15 -> ንሳ ከኣ መጺኣ። | G15: ='Word List'!J15 -> nisa ke'a mets'i'a. | H15: ='Word List'!K15 -> And she came too.
A16: ='Word List'!G17 -> Grammar Essentials | B16: ='Word List'!A17 -> 16 | C16: ='Word List'!B17 -> ግን | D16: ='Word List'!D17 -> gin | E16: ='Word List'!E17 -> but | F16: ='Word List'!I17 -> ደኺመ ግን ሕጉስ እየ። | G16: ='Word List'!J17 -> dekhime gin higus iye. | H16: ='Word List'!K17 -> I'm tired, but I'm happy.
A17: ='Word List'!G19 -> Grammar Essentials | B17: ='Word List'!A19 -> 18 | C17: ='Word List'!B19 -> ወይ | D17: ='Word List'!D19 -> wey | E17: ='Word List'!E19 -> or | F17: ='Word List'!I19 -> ሻሂ ወይ ቡን? | G17: ='Word List'!J19 -> shahi wey bun? | H17: ='Word List'!K19 -> Tea or coffee?
A18: ='Word List'!G20 -> Grammar Essentials | B18: ='Word List'!A20 -> 19 | C18: ='Word List'!B20 -> እውን | D18: ='Word List'!D20 -> i-wun | E18: ='Word List'!E20 -> also, too | F18: ='Word List'!I20 -> ኣነ እውን ክመጽእ እየ። | G18: ='Word List'!J20 -> ane iwun kimets'i iye. | H18: ='Word List'!K20 -> I will come too.
A19: ='Word List'!G28 -> Grammar Essentials | B19: ='Word List'!A28 -> 27 | C19: ='Word List'!B28 -> እዮም | D19: ='Word List'!D28 -> i-yom | E19: ='Word List'!E28 -> are (they are) | F19: ='Word List'!I28 -> ንሳቶም ኣሕዋተይ እዮም። | G19: ='Word List'!J28 -> nisatom ahwatey iyom. | H19: ='Word List'!K28 -> They are my brothers.
A20: ='Word List'!G34 -> Grammar Essentials | B20: ='Word List'!A34 -> 33 | C20: ='Word List'!B34 -> ኣሎ | D20: ='Word List'!D34 -> al-lo | E20: ='Word List'!E34 -> there is; he/it is (here) | F20: ='Word List'!I34 -> ማይ ኣሎ ድዩ? | G20: ='Word List'!J34 -> may allo diyu? | H20: ='Word List'!K34 -> Is there water?
A21: ='Word List'!G40 -> Grammar Essentials | B21: ='Word List'!A40 -> 39 | C21: ='Word List'!B40 -> እታ | D21: ='Word List'!D40 -> i-ta | E21: ='Word List'!E40 -> the; that (feminine) | F21: ='Word List'!I40 -> እታ ጓል | G21: ='Word List'!J40 -> ita gwal | H21: ='Word List'!K40 -> the girl
A22: ='Word List'!G55 -> Grammar Essentials | B22: ='Word List'!A55 -> 54 | C22: ='Word List'!B55 -> ኢና | D22: ='Word List'!D55 -> i-na | E22: ='Word List'!E55 -> are (we are) | F22: ='Word List'!I55 -> ኤርትራውያን ኢና። | G22: ='Word List'!J55 -> ertrawyan ina. | H22: ='Word List'!K55 -> We are Eritreans.
A23: ='Word List'!G57 -> Grammar Essentials | B23: ='Word List'!A57 -> 56 | C23: ='Word List'!B57 -> ኣብዚ | D23: ='Word List'!D57 -> ab-zi | E23: ='Word List'!E57 -> here; in this | F23: ='Word List'!I57 -> ኣብዚ ተቐመጥ። | G23: ='Word List'!J57 -> abzi teqemet'. | H23: ='Word List'!K57 -> Sit here. (to a boy)
A24: ='Word List'!G58 -> Grammar Essentials | B24: ='Word List'!A58 -> 57 | C24: ='Word List'!B58 -> እያ | D24: ='Word List'!D58 -> i-ya | E24: ='Word List'!E58 -> is (she is) | F24: ='Word List'!I58 -> ንሳ ሓብተይ እያ። | G24: ='Word List'!J58 -> nisa habtey iya. | H24: ='Word List'!K58 -> She is my sister.
A25: ='Word List'!G62 -> Grammar Essentials | B25: ='Word List'!A62 -> 61 | C25: ='Word List'!B62 -> ኣነ | D25: ='Word List'!D62 -> a-ne | E25: ='Word List'!E62 -> I; me | F25: ='Word List'!I62 -> ኣነ ሳባ እየ። | G25: ='Word List'!J62 -> ane saba iye. | H25: ='Word List'!K62 -> I am Saba.
A26: ='Word List'!G63 -> Grammar Essentials | B26: ='Word List'!A63 -> 62 | C26: ='Word List'!B63 -> እየ | D26: ='Word List'!D63 -> i-ye | E26: ='Word List'!E63 -> am (I am) | F26: ='Word List'!I63 -> ደሓን እየ። | G26: ='Word List'!J63 -> dehan iye. | H26: ='Word List'!K63 -> I am fine.
A27: ='Word List'!G107 -> Grammar Essentials | B27: ='Word List'!A107 -> 106 | C27: ='Word List'!B107 -> ንሱ | D27: ='Word List'!D107 -> ni-su | E27: ='Word List'!E107 -> he; him | F27: ='Word List'!I107 -> ንሱ ሓወይ እዩ። | G27: ='Word List'!J107 -> nisu hawey iyu. | H27: ='Word List'!K107 -> He is my brother.
A28: ='Word List'!G110 -> Grammar Essentials | B28: ='Word List'!A110 -> 109 | C28: ='Word List'!B110 -> ከምዚ | D28: ='Word List'!D110 -> kem-zi | E28: ='Word List'!E110 -> like this; this way | F28: ='Word List'!I110 -> ከምዚ ግበር። | G28: ='Word List'!J110 -> kemzi giber. | H28: ='Word List'!K110 -> Do it like this. (to a boy)
A29: ='Word List'!G126 -> Grammar Essentials | B29: ='Word List'!A126 -> 125 | C29: ='Word List'!B126 -> ኣለዎ | D29: ='Word List'!D126 -> al-le-wo | E29: ='Word List'!E126 -> he/it has | F29: ='Word List'!I126 -> ንሱ ድሙ ኣለዎ። | G29: ='Word List'!J126 -> nisu dimmu allewo. | H29: ='Word List'!K126 -> He has a cat.
A30: ='Word List'!G130 -> Grammar Essentials | B30: ='Word List'!A130 -> 129 | C30: ='Word List'!B130 -> ኢኻ | D30: ='Word List'!D130 -> i-kha | E30: ='Word List'!E130 -> are (you are, to a boy/man) | F30: ='Word List'!I130 -> ጐበዝ ኢኻ! | G30: ='Word List'!J130 -> gobez ikha! | H30: ='Word List'!K130 -> You're great! / Well done! (to a boy)
A31: ='Word List'!G157 -> Grammar Essentials | B31: ='Word List'!A157 -> 156 | C31: ='Word List'!B157 -> ውሽጢ | D31: ='Word List'!D157 -> wish-t'i | E31: ='Word List'!E157 -> inside | F31: ='Word List'!I157 -> ኣብ ውሽጢ ገዛ | G31: ='Word List'!J157 -> ab wisht'i geza | H31: ='Word List'!K157 -> inside the house
A32: ='Word List'!G178 -> Grammar Essentials | B32: ='Word List'!A178 -> 177 | C32: ='Word List'!B178 -> እዛ | D32: ='Word List'!D178 -> i-za | E32: ='Word List'!E178 -> this (feminine) | F32: ='Word List'!I178 -> እዛ ጓል ሓብተይ እያ። | G32: ='Word List'!J178 -> iza gwal habtey iya. | H32: ='Word List'!K178 -> This girl is my sister.
A33: ='Word List'!G189 -> Grammar Essentials | B33: ='Word List'!A189 -> 188 | C33: ='Word List'!B189 -> ትሕቲ | D33: ='Word List'!D189 -> tih-ti | E33: ='Word List'!E189 -> under; below | F33: ='Word List'!I189 -> ኣብ ትሕቲ ጠረጴዛ | G33: ='Word List'!J189 -> ab tihti t'erep'eza | H33: ='Word List'!K189 -> under the table
A34: ='Word List'!G195 -> Grammar Essentials | B34: ='Word List'!A195 -> 194 | C34: ='Word List'!B195 -> ኣለዉ | D34: ='Word List'!D195 -> al-le-wu | E34: ='Word List'!E195 -> they are (here); there are | F34: ='Word List'!I195 -> ኣሕዋተይ ኣብ ገዛ ኣለዉ። | G34: ='Word List'!J195 -> ahwatey ab geza allewu. | H34: ='Word List'!K195 -> My brothers are at home.
A35: ='Word List'!G204 -> Grammar Essentials | B35: ='Word List'!A204 -> 203 | C35: ='Word List'!B204 -> ኣይኮነን | D35: ='Word List'!D204 -> ay-ko-nen | E35: ='Word List'!E204 -> is not; no, it isn't | F35: ='Word List'!I204 -> እዚ ናተይ ኣይኮነን። | G35: ='Word List'!J204 -> izi natey aykonen. | H35: ='Word List'!K204 -> This is not mine.
A36: ='Word List'!G243 -> Grammar Essentials | B36: ='Word List'!A243 -> 242 | C36: ='Word List'!B243 -> ንዓይ | D36: ='Word List'!D243 -> ni-ay | E36: ='Word List'!E243 -> me; to me; for me | F36: ='Word List'!I243 -> ንዓይ ሃበኒ። | G36: ='Word List'!J243 -> ni'ay habeni. | H36: ='Word List'!K243 -> Give it to me. (to a boy)
A37: ='Word List'!G261 -> Grammar Essentials | B37: ='Word List'!A261 -> 260 | C37: ='Word List'!B261 -> ምኽንያቱ | D37: ='Word List'!D261 -> mikh-ni-ya-tu | E37: ='Word List'!E261 -> because | F37: ='Word List'!I261 -> ኣይመጻእኩን፡ ምኽንያቱ ሓሚመ ነይረ። | G37: ='Word List'!J261 -> aymets'a'kun, mikhniyatu hamime neyre. | H37: ='Word List'!K261 -> I didn't come because I was sick.
A38: ='Word List'!G267 -> Grammar Essentials | B38: ='Word List'!A267 -> 266 | C38: ='Word List'!B267 -> ኣለኹ | D38: ='Word List'!D267 -> al-le-khu | E38: ='Word List'!E267 -> I am (here); I am (doing) | F38: ='Word List'!I267 -> ኣብዚ ኣለኹ! | G38: ='Word List'!J267 -> abzi allekhu! | H38: ='Word List'!K267 -> I'm here!
A39: ='Word List'!G318 -> Grammar Essentials | B39: ='Word List'!A318 -> 317 | C39: ='Word List'!B318 -> የለን | D39: ='Word List'!D318 -> ye-len | E39: ='Word List'!E318 -> there isn't; no; is not here | F39: ='Word List'!I318 -> ኣቦይ ኣብ ገዛ የለን። | G39: ='Word List'!J318 -> aboy ab geza yelen. | H39: ='Word List'!K318 -> My dad isn't home.
A40: ='Word List'!G327 -> Grammar Essentials | B40: ='Word List'!A327 -> 326 | C40: ='Word List'!B327 -> ንሕና | D40: ='Word List'!D327 -> nih-na | E40: ='Word List'!E327 -> we; us | F40: ='Word List'!I327 -> ንሕና ኤርትራውያን ኢና። | G40: ='Word List'!J327 -> nihna ertrawyan ina. | H40: ='Word List'!K327 -> We are Eritreans.
A41: ='Word List'!G339 -> Grammar Essentials | B41: ='Word List'!A339 -> 338 | C41: ='Word List'!B339 -> ኣብኡ | D41: ='Word List'!D339 -> ab-u | E41: ='Word List'!E339 -> there; in it | F41: ='Word List'!I339 -> ኣብኡ ኣሎ። | G41: ='Word List'!J339 -> ab'u allo. | H41: ='Word List'!K339 -> It's there.
...

Sheet Pronunciation Guide
A1: How to read the romanized pronunciations
A2: Tigrinya is written in the Ge'ez script (ፊደል). Each letter is a consonant + vowel. These spellings help English readers say the words.
A4: You see | B4: Say it like | C4: Ge'ez letters | D4: Example | E4: Example meaning
A5: VOWELS
A6: a | B6: 'a' in father | C6: ኣ ባ ማ | D6: ማይ — may | E6: water
A7: e | B7: 'e' in bed | C7: ሰ ቤ ከ | D7: ሰላም — se-lam | E7: hello; peace
A8: i | B8: 'i' in sit (often short and light) | C8: ኢ ብ ሚ | D8: ሕጂ — hi-ji | E8: now
A9: o | B9: 'o' in go | C9: ኦ ሎ ቦ | D9: ሎሚ — lo-mi | E9: today
A10: u | B10: 'oo' in food | C10: ኡ ሱ ቡ | D10: ንሱ — ni-su | E10: he
A11: SOUNDS ENGLISH DOESN'T HAVE
A12: t' | B12: 't' with a pop: hold your breath, then let the t burst out | C12: ጠ ጥ ጣ | D12: ጥራይ — t'i-ray | E12: only
A13: ts' | B13: 'ts' (as in cats) with a pop | C13: ጸ ጽ ጻ | D13: ጽቡቕ — ts'i-buq | E13: good
A14: ch' | B14: 'ch' with a pop | C14: ጨ ጭ ጫ | D14: ጫማ — ch'am-ma | E14: shoes
A15: p' | B15: 'p' with a pop | C15: ጰ ጵ | D15: ኢትዮጵያ — it-yo-p'i-ya | E15: Ethiopia
A16: q | B16: a deep 'k' made at the very back of the throat | C16: ቀ ቐ ቕ ቑ | D16: ቀይሕ — qe-yih | E16: red
A17: kh | B17: a soft, breathy throat sound, like the end of 'Bach' | C17: ኸ ኽ ኻ | D17: ኣምላኽ — am-lakh | E17: God
A18: h | B18: 'h' — ሐ/ሓ is a stronger, raspier h than ሀ/ሃ | C18: ሀ ሃ ሐ ሓ | D18: ሓደ — ha-de | E18: one
A19: ' (in the middle) | B19: a tiny catch in the throat, like the break in 'uh-oh' | C19: እ ዕ ዓ | D19: ማእከል — ma'-kel | E19: center
A20: FAMILIAR SOUNDS
A21: ch | B21: 'ch' in church | C21: ቸ ቹ | D21: ቸልሲ — chel-si | E21: Chelsea
A22: sh | B22: 'sh' in ship | C22: ሸ ሽ | D22: ሽሕ — shih | E22: thousand
A23: j | B23: 'j' in jam | C23: ጀ ጅ | D23: ጀመረ — je-me-re | E23: he started
A24: ny | B24: 'ny' in canyon | C24: ኘ ኛ | D24: ትግርኛ — tig-ri-nya | E24: Tigrinya
A25: gw / kw / qw | B25: round your lips for a little 'w' | C25: ጓ ኳ ቋ | D25: ቋንቋ — qwan-qwa | E25: language
A26: READING TIPS
A27: Hyphens | B27: Separate syllables. Say each part clearly and evenly. | D27: ትምህርቲ — tim-hir-ti | E27: education
A28: Double letters | B28: Hold the sound a little longer. | D28: ኩሉ — kul-lu | E28: all
A29: k → kh | B29: After a vowel, k often softens to kh, and the spelling can change too. | C29: ከ → ኸ | D29: ከም → ኸም | E29: like, as
A30: Apostrophes in examples | B30: In example sentences, a word like izi'yu shows a contraction, the same as in the Tigrinya (እዚ'ዩ). | D30: እዚ'ዩ — izi'yu | E30: this is it

Sheet Word List
A1: Rank | B1: Tigrinya Word | C1: Frequency | D1: Pronunciation | E1: English Meaning | F1: Word Type | G1: Topic | H1: Level | I1: Example (Tigrinya) | J1: Example (Romanized) | K1: Example (English) | L1: Learning Note | M1: Needs Review
A2: 1 | B2: ኣብ | C2: 2047826 | D2: ab | E2: at, in, on | F2: Preposition | G2: Grammar Essentials | H2: 1 Starter | I2: ኣብ ገዛ ኣለኹ። | J2: ab geza allekhu. | K2: I am at home. | L2: The #1 most common word in Tigrinya. It tells WHERE something is. Often joins the next word: ኣብቲ (in the), ኣብዚ (here).
A3: 2 | B3: ናይ | C3: 675275 | D3: nay | E3: of; belonging to ('s) | F3: Preposition | G3: Grammar Essentials | H3: 1 Starter | I3: ናይ ኣደይ መኪና | J3: nay adey mekina | K3: my mother's car | L3: Works like English "'s" or "of". ናይ መን? = whose?
A4: 3 | B4: እዩ | C4: 583384 | D4: i-yu | E4: is (he/it is) | F4: Linking word (is/am/are) | G4: Grammar Essentials | H4: 1 Starter | I4: እዚ ማይ እዩ። | J4: izi may iyu. | K4: This is water. | L4: A linking word that goes at the END of the sentence. It changes with the subject: እየ (I am), ኢኻ (you are), እያ (she is), እዮም (they are).
A5: 4 | B5: ካብ | C5: 562897 | D5: kab | E5: from | F5: Preposition | G5: Grammar Essentials | H5: 1 Starter | I5: ካብ ኣስመራ እየ። | J5: kab asmera iye. | K5: I am from Asmara. | L5: After a vowel it can be written ኻብ (khab). ካብ ... ክሳብ = from ... until.
A6: 5 | B6: ከም | C6: 494067 | D6: kem | E6: like, as | F6: Preposition | G6: Grammar Essentials | H6: 1 Starter | I6: ከም ኣቦኻ ኢኻ። | J6: kem abokha ikha. | K6: You are like your father. | L6: After a vowel it often softens to ኸም (khem). ከምዚ = like this.
A7: 6 | B7: እቲ | C7: 493726 | D7: i-ti | E7: the; that (masculine) | F7: Pointing word (the/this/that) | G7: Grammar Essentials | H7: 1 Starter | I7: እቲ ቈልዓ ይጻወት ኣሎ። | J7: iti qol'a yits'awet allo. | K7: The child is playing. | L7: Used with masculine words. Feminine: እታ. Plural: እቶም / እተን.
A8: 7 | B8: ድማ | C8: 450747 | D8: dim-ma | E8: and; also | F8: Connector (conjunction) | G8: Grammar Essentials | H8: 1 Starter | I8: ኣነ ድማ ክመጽእ እየ። | J8: ane dimma kimets'i iye. | K8: And I will come too. | L8: Comes AFTER the word it links (ኣነ ድማ = "and I"). Means about the same as ከኣ.
A9: 8 | B9: ምስ | C9: 449626 | D9: mis | E9: with | F9: Preposition | G9: Grammar Essentials | H9: 1 Starter | I9: ምስ ኣደይ ከይደ። | J9: mis adey keyde. | K9: I went with my mother. | L9: Before a verb it can mean "when": ምስ መጸ = when he came.
A10: 9 | B10: ናብ | C10: 329635 | D10: nab | E10: to, toward | F10: Preposition | G10: Grammar Essentials | H10: 1 Starter | I10: ናብ ቤት ትምህርቲ ንኸይድ ኣለና። | J10: nab bet timhirti nikheyd allena. | K10: We are going to school. | L10: Shows direction (where you are going). ናብዚ = to here.
A11: 10 | B11: እዚ | C11: 297664 | D11: i-zi | E11: this (masculine) | F11: Pointing word (the/this/that) | G11: Grammar Essentials | H11: 1 Starter | I11: እዚ እንታይ እዩ? | J11: izi intay iyu? | K11: What is this? | L11: Feminine: እዛ. Plural: እዞም / እዘን. One of the first words to learn!
A12: 11 | B12: ዩ | C12: 267828 | D12: yu | E12: is (short form of እዩ) | F12: Short / split form | G12: Grammar Essentials | H12: 2 Core | I12: እዚ'ዩ። | J12: izi'yu. | K12: This is it. | L12: Contracted form of እዩ, written after an apostrophe when the word before ends in a vowel. It shows up as its own "word" because of how the text was split.
A13: 12 | B13: ነቲ | C13: 216027 | D13: ne-ti | E13: the (as the object); to the (masculine) | F13: Pointing word (the/this/that) | G13: Grammar Essentials | H13: 2 Core | I13: ነቲ መጽሓፍ ሃበኒ። | J13: neti mets'haf habeni. | K13: Give me the book. | L13: ን + እቲ. Used when "the ___" receives the action. Feminine: ነታ.
... A65: 64 | B65: ዓለም | C65: 72009 | D65: a-lem | E65: world | F65: Noun | G65: Places & Geography | H65: 2 Core | I65: ኣብ ምሉእ ዓለም | J65: ab milu' alem | K65: in the whole world | L65: Also a girl's name (ዓለም).
A66: 65 | B66: ኮይኑ | C66: 71805 | D66: koy-nu | E66: being; having become | F66: Verb form | G66: Grammar Essentials | H66: 3 Advanced | I66: ሓሚሙ ኮይኑ። | J66: hamimu koynu. | K66: It turns out he is sick. | L66: From ኮነ (became; was). Variant spellings: ኰይኑ, ዀይኑ. | M66: Check
A67: 66 | B67: ዘለዎ | C67: 71773 | D67: zel-le-wo | E67: that has; which (he/it) has | F67: Verb form | G67: Grammar Essentials | H67: 3 Advanced | I67: ቀይሕ መኪና ዘለዎ ሰብ | J67: qeyih mekina zellewo seb | K67: the man who has a red car | L67: From ኣለዎ (he has).
A68: 67 | B68: ስራሕ | C68: 70712 | D68: si-rah | E68: work; job | F68: Noun | G68: Work & Money | H68: 1 Starter | I68: ኣቦይ ናብ ስራሕ ከይዱ። | J68: aboy nab sirah keydu. | K68: My dad went to work. | L68: Plural: ስራሓት. ዕዮ also means work.
A69: 68 | B69: ኢሉ | C69: 69907 | D69: i-lu | E69: saying; having said (he) | F69: Verb form | G69: Grammar Essentials | H69: 2 Core | I69: "ሰላም" ኢሉ። | J69: "selam" ilu. | K69: He said "hello". | L69: From በለ (to say). She said: ኢላ. They said: ኢሎም.
A70: 69 | B70: ክልተ | C70: 69688 | D70: kil-te | E70: two | F70: Number | G70: Numbers & Amounts | H70: 1 Starter | I70: ክልተ ኣዒንቲ | J70: kilte a'inti | K70: two eyes | L70: Number 2. ካልኣይ = second.
A71: 70 | B71: ዝብል | C71: 69273 | D71: zi-bil | E71: that says; called | F71: Verb form | G71: Grammar Essentials | H71: 3 Advanced | I71: ሰላም ዝብል ቃል | J71: selam zibil qal | K71: the word "selam" (lit. "the word that says selam") | L71: From ይብል (he says). Used for quotes and titles.
A72: 71 | B72: ሕጂ | C72: 69041 | D72: hi-ji | E72: now | F72: Adverb | G72: Time & Calendar | H72: 1 Starter | I72: ሕጂ ንዓ! | J72: hiji n'a! | K72: Come now! (to a boy) | L72: ክሳብ ሕጂ = until now.
A73: 72 | B73: ነገር | C73: 68381 | D73: ne-ger | E73: thing; matter | F73: Noun | G73: Home & Everyday Life | H73: 1 Starter | I73: እዚ ነገር እንታይ እዩ? | J73: izi neger intay iyu? | K73: What is this thing? | L73: Plural: ነገራት.
A74: 73 | B74: እንተሎ | C74: 67075 | D74: in-tel-lo | E74: if there is | F74: Verb form | G74: Grammar Essentials | H74: 3 Advanced | I74: ሕቶ እንተሎ ሕተቱ። | J74: hito intello hitetu. | K74: If there is a question, ask. | L74: እንተ (if) + ኣሎ (there is). Very common here from court notices: ዝቃወም እንተሎ = "if anyone objects".
A75: 74 | B75: ብዙሕ | C75: 66437 | D75: bi-zuh | E75: much; many; a lot | F75: Adjective | G75: Describing Words | H75: 1 Starter | I75: ብዙሕ የቐንየለይ። | J75: bizuh yeqenyeley. | K75: Thank you very much. | L75: Plural form: ብዙሓት. A must-know phrase!
A76: 75 | B76: ኩሉ | C76: 65760 | D76: kul-lu | E76: all; everything | F76: Adjective | G76: Describing Words | H76: 1 Starter | I76: ኩሉ ጽቡቕ እዩ። | J76: kullu ts'ibuq iyu. | K76: Everything is good. | L76: ኩሎም = all of them (people). Variant spellings: ኵሉ, ዅሉ.
A77: 76 | B77: ከተማ | C77: 65392 | D77: ke-te-ma | E77: city, town | F77: Noun | G77: Places & Geography | H77: 1 Starter | I77: ኣስመራ ርእሰ ከተማ ኤርትራ እያ። | J77: asmera ri'se ketema ertra iya. | K77: Asmara is the capital city of Eritrea. | L77: Plural: ከተማታት.
A78: 77 | B78: ገለ | C78: 65240 | D78: ge-le | E78: some; something | F78: Adjective | G78: Describing Words | H78: 2 Core | I78: ገለ ማይ ሃበኒ። | J78: gele may habeni. | K78: Give me some water. (to a man/boy) | L78: ገለ ነገር = something. ገሊኦም = some of them.
... A174: 173 | B174: ከመይ | C174: 33742 | D174: ke-mey | E174: how? | F174: Question word | G174: Questions | H174: 1 Starter | I174: ከመይ ኣለኻ? | J174: kemey allekha? | K174: How are you? (to a boy/man) | L174: The #1 greeting! To a girl: ከመይ ኣለኺ? To a group: ከመይ ኣለኹም? Answer: ደሓን እየ (I'm fine).
A175: 174 | B175: ኮማዊ | C175: 33684 | D175: ko-ma-wi | E175: (meaning uncertain) | F175: Adjective | G175: News & Government | H175: 4 Specialized | I175: — | J175: — | K175: — | L175: Appears very often in the source data (probably in formal/official notices) but is rare in everyday Tigrinya. Please confirm the meaning with a fluent speaker before teaching it. | M175: Check
A176: 175 | B176: ብኸመይ | C176: 33659 | D176: bi-khe-mey | E176: how? in what way? | F176: Question word | G176: Questions | H176: 2 Core | I176: ብትግርኛ ብኸመይ ይበሃል? | J176: bitigrinya bikhemey yibehal? | K176: How do you say it in Tigrinya? | L176: Super useful for learners! ብ + ከመይ.
A177: 176 | B177: ሕማም | C177: 33585 | D177: hi-mam | E177: illness; disease; pain | F177: Noun | G177: Body & Health | H177: 2 Core | I177: ሕማም ርእሲ | J177: himam ri'si | K177: headache | L177: ሓሚመ = I'm sick. Plural: ሕማማት.
A178: 177 | B178: እዛ | C178: 33536 | D178: i-za | E178: this (feminine) | F178: Pointing word (the/this/that) | G178: Grammar Essentials | H178: 1 Starter | I178: እዛ ጓል ሓብተይ እያ። | J178: iza gwal habtey iya. | K178: This girl is my sister. | L178: Feminine of እዚ.
A179: 178 | B179: መንጎ | C179: 33461 | D179: men-go | E179: between; among | F179: Preposition | G179: Grammar Essentials | H179: 2 Core | I179: ኣብ መንጎ ክልተ ገዛውቲ | J179: ab mengo kilte gezawti | K179: between two houses | L179: ኣብ መንጎ = between.
A180: 179 | B180: ጸወታ | C180: 33205 | D180: ts'e-we-ta | E180: game; play | F180: Noun | G180: Sports & Games | H180: 1 Starter | I180: ጸወታ ኩዕሶ | J180: ts'eweta ku'so | K180: a ball game | L180: Plural: ጸወታታት. ንጻወት! = Let's play!
A181: 180 | B181: ሰዓት | C181: 33199 | D181: se-at | E181: hour; o'clock; clock, watch | F181: Noun | G181: Time & Calendar | H181: 1 Starter | I181: ሰዓት ክንደይ እዩ? | J181: se'at kindey iyu? | K181: What time is it? | L181: Must-know question! Plural: ሰዓታት.
A182: 181 | B182: ዝበለ | C182: 33160 | D182: zi-be-le | E182: who said; that said | F182: Verb form | G182: Grammar Essentials | H182: 3 Advanced | I182: ሰላም ዝበለ ሰብ | J182: selam zibele seb | K182: the person who said hello | L182: From በለ (said). Plural: ዝበሉ.
A183: 182 | B183: ቀዳማይ | C183: 33142 | D183: qe-da-may | E183: first | F183: Adjective | G183: Numbers & Amounts | H183: 1 Starter | I183: ቀዳማይ ክፍሊ | J183: qedamay kifli | K183: first grade | L183: Feminine: ቀዳመይቲ. Second: ካልኣይ. Third: ሳልሳይ.
A184: 183 | B184: የሱስ | C184: 33129 | D184: ye-sus | E184: Jesus | F184: Other name | G184: Faith & Religion | H184: 2 Core | I184: የሱስ ክርስቶስ | J184: yesus kristos | K184: Jesus Christ | L184: Heard often in church and Christian homes.
A185: 184 | B185: ሕጊ | C185: 32717 | D185: hi-gi | E185: law; rule | F185: Noun | G185: Law & Courts | H185: 3 Advanced | I185: ሕጊ ቤት ትምህርቲ | J185: higi bet timhirti | K185: school rules | L185: Plural: ሕግታት. ሕጋዊ = legal.
A186: 185 | B186: ዋላ | C186: 32500 | D186: wal-la | E186: even; even if | F186: Particle | G186: Grammar Essentials | H186: 2 Core | I186: ዋላ ሓደ | J186: walla hade | K186: not even one; none | L186: ዋላ'ኳ = even though.
...

Sheet Summary
A1: Summary — words by topic and level
A2: All counts are formulas over the Word List and update if you change a Topic or Level there.
A4: Topic | B4: 1 Starter | C4: 2 Core | D4: 3 Advanced | E4: 4 Specialized | F4: Total
A5: Actions | B5: =COUNTIFS('Word List'!$G$2:$G$1001,$A5,'Word List'!$H$2:$H$1001,B$4) -> 3 | C5: =COUNTIFS('Word List'!$G$2:$G$1001,$A5,'Word List'!$H$2:$H$1001,C$4) -> 24 | D5: =COUNTIFS('Word List'!$G$2:$G$1001,$A5,'Word List'!$H$2:$H$1001,D$4) -> 4 | E5: =COUNTIFS('Word List'!$G$2:$G$1001,$A5,'Word List'!$H$2:$H$1001,E$4) -> 0 | F5: =SUM(B5:E5) -> 31
A6: Body & Health | B6: =COUNTIFS('Word List'!$G$2:$G$1001,$A6,'Word List'!$H$2:$H$1001,B$4) -> 6 | C6: =COUNTIFS('Word List'!$G$2:$G$1001,$A6,'Word List'!$H$2:$H$1001,C$4) -> 11 | D6: =COUNTIFS('Word List'!$G$2:$G$1001,$A6,'Word List'!$H$2:$H$1001,D$4) -> 9 | E6: =COUNTIFS('Word List'!$G$2:$G$1001,$A6,'Word List'!$H$2:$H$1001,E$4) -> 0 | F6: =SUM(B6:E6) -> 26
A7: Culture & Celebrations | B7: =COUNTIFS('Word List'!$G$2:$G$1001,$A7,'Word List'!$H$2:$H$1001,B$4) -> 1 | C7: =COUNTIFS('Word List'!$G$2:$G$1001,$A7,'Word List'!$H$2:$H$1001,C$4) -> 8 | D7: =COUNTIFS('Word List'!$G$2:$G$1001,$A7,'Word List'!$H$2:$H$1001,D$4) -> 1 | E7: =COUNTIFS('Word List'!$G$2:$G$1001,$A7,'Word List'!$H$2:$H$1001,E$4) -> 0 | F7: =SUM(B7:E7) -> 10
A8: Describing Words | B8: =COUNTIFS('Word List'!$G$2:$G$1001,$A8,'Word List'!$H$2:$H$1001,B$4) -> 15 | C8: =COUNTIFS('Word List'!$G$2:$G$1001,$A8,'Word List'!$H$2:$H$1001,C$4) -> 34 | D8: =COUNTIFS('Word List'!$G$2:$G$1001,$A8,'Word List'!$H$2:$H$1001,D$4) -> 18 | E8: =COUNTIFS('Word List'!$G$2:$G$1001,$A8,'Word List'!$H$2:$H$1001,E$4) -> 2 | F8: =SUM(B8:E8) -> 69
A9: Faith & Religion | B9: =COUNTIFS('Word List'!$G$2:$G$1001,$A9,'Word List'!$H$2:$H$1001,B$4) -> 0 | C9: =COUNTIFS('Word List'!$G$2:$G$1001,$A9,'Word List'!$H$2:$H$1001,C$4) -> 7 | D9: =COUNTIFS('Word List'!$G$2:$G$1001,$A9,'Word List'!$H$2:$H$1001,D$4) -> 11 | E9: =COUNTIFS('Word List'!$G$2:$G$1001,$A9,'Word List'!$H$2:$H$1001,E$4) -> 2 | F9: =SUM(B9:E9) -> 20
A10: Feelings & Values | B10: =COUNTIFS('Word List'!$G$2:$G$1001,$A10,'Word List'!$H$2:$H$1001,B$4) -> 9 | C10: =COUNTIFS('Word List'!$G$2:$G$1001,$A10,'Word List'!$H$2:$H$1001,C$4) -> 16 | D10: =COUNTIFS('Word List'!$G$2:$G$1001,$A10,'Word List'!$H$2:$H$1001,D$4) -> 7 | E10: =COUNTIFS('Word List'!$G$2:$G$1001,$A10,'Word List'!$H$2:$H$1001,E$4) -> 0 | F10: =SUM(B10:E10) -> 32
A11: Food & Drink | B11: =COUNTIFS('Word List'!$G$2:$G$1001,$A11,'Word List'!$H$2:$H$1001,B$4) -> 3 | C11: =COUNTIFS('Word List'!$G$2:$G$1001,$A11,'Word List'!$H$2:$H$1001,C$4) -> 3 | D11: =COUNTIFS('Word List'!$G$2:$G$1001,$A11,'Word List'!$H$2:$H$1001,D$4) -> 1 | E11: =COUNTIFS('Word List'!$G$2:$G$1001,$A11,'Word List'!$H$2:$H$1001,E$4) -> 0 | F11: =SUM(B11:E11) -> 7
A12: Grammar Essentials | B12: =COUNTIFS('Word List'!$G$2:$G$1001,$A12,'Word List'!$H$2:$H$1001,B$4) -> 49 | C12: =COUNTIFS('Word List'!$G$2:$G$1001,$A12,'Word List'!$H$2:$H$1001,C$4) -> 101 | D12: =COUNTIFS('Word List'!$G$2:$G$1001,$A12,'Word List'!$H$2:$H$1001,D$4) -> 129 | E12: =COUNTIFS('Word List'!$G$2:$G$1001,$A12,'Word List'!$H$2:$H$1001,E$4) -> 6 | F12: =SUM(B12:E12) -> 285
A13: Home & Everyday Life | B13: =COUNTIFS('Word List'!$G$2:$G$1001,$A13,'Word List'!$H$2:$H$1001,B$4) -> 5 | C13: =COUNTIFS('Word List'!$G$2:$G$1001,$A13,'Word List'!$H$2:$H$1001,C$4) -> 8 | D13: =COUNTIFS('Word List'!$G$2:$G$1001,$A13,'Word List'!$H$2:$H$1001,D$4) -> 2 | E13: =COUNTIFS('Word List'!$G$2:$G$1001,$A13,'Word List'!$H$2:$H$1001,E$4) -> 2 | F13: =SUM(B13:E13) -> 17
A14: Law & Courts | B14: =COUNTIFS('Word List'!$G$2:$G$1001,$A14,'Word List'!$H$2:$H$1001,B$4) -> 0 | C14: =COUNTIFS('Word List'!$G$2:$G$1001,$A14,'Word List'!$H$2:$H$1001,C$4) -> 0 | D14: =COUNTIFS('Word List'!$G$2:$G$1001,$A14,'Word List'!$H$2:$H$1001,D$4) -> 2 | E14: =COUNTIFS('Word List'!$G$2:$G$1001,$A14,'Word List'!$H$2:$H$1001,E$4) -> 27 | F14: =SUM(B14:E14) -> 29
A15: Names | B15: =COUNTIFS('Word List'!$G$2:$G$1001,$A15,'Word List'!$H$2:$H$1001,B$4) -> 0 | C15: =COUNTIFS('Word List'!$G$2:$G$1001,$A15,'Word List'!$H$2:$H$1001,C$4) -> 0 | D15: =COUNTIFS('Word List'!$G$2:$G$1001,$A15,'Word List'!$H$2:$H$1001,D$4) -> 0 | E15: =COUNTIFS('Word List'!$G$2:$G$1001,$A15,'Word List'!$H$2:$H$1001,E$4) -> 22 | F15: =SUM(B15:E15) -> 22
A16: Nature & Animals | B16: =COUNTIFS('Word List'!$G$2:$G$1001,$A16,'Word List'!$H$2:$H$1001,B$4) -> 3 | C16: =COUNTIFS('Word List'!$G$2:$G$1001,$A16,'Word List'!$H$2:$H$1001,C$4) -> 8 | D16: =COUNTIFS('Word List'!$G$2:$G$1001,$A16,'Word List'!$H$2:$H$1001,D$4) -> 2 | E16: =COUNTIFS('Word List'!$G$2:$G$1001,$A16,'Word List'!$H$2:$H$1001,E$4) -> 0 | F16: =SUM(B16:E16) -> 13
... A25: Work & Money | B25: =COUNTIFS('Word List'!$G$2:$G$1001,$A25,'Word List'!$H$2:$H$1001,B$4) -> 1 | C25: =COUNTIFS('Word List'!$G$2:$G$1001,$A25,'Word List'!$H$2:$H$1001,C$4) -> 4 | D25: =COUNTIFS('Word List'!$G$2:$G$1001,$A25,'Word List'!$H$2:$H$1001,D$4) -> 11 | E25: =COUNTIFS('Word List'!$G$2:$G$1001,$A25,'Word List'!$H$2:$H$1001,E$4) -> 3 | F25: =SUM(B25:E25) -> 19
A26: Total | B26: =SUM(B5:B25) -> 182 | C26: =SUM(C5:C25) -> 341 | D26: =SUM(D5:D25) -> 367 | E26: =SUM(E5:E25) -> 110 | F26: =SUM(F5:F25) -> 1000
A28: Words marked "Check" | B28: =COUNTIF('Word List'!$M$2:$M$1001,"Check") -> 7
A29: Starter Words listed | B29: =COUNTA('Starter Words'!$B$5:$B$186) -> 182
